Workbook

Sheet How to use
A1: Eduplan student tools: data workbook
A3: What this is | B3: All the information the Eduplan website needs for its three tools, plus a tracker for every student who uses each one.
A5: Tabs
A6: Fields | B6: Shared list of fields of study. Every tool uses these IDs.
A7: Universities | B7: Shared list of partner universities and colleges, with hostel and rent (used by Accommodation).
A8: 1 Scholarships | B8: Option 1, Scholarship-based: every scholarship and who can get it.
A9: 1 Scholarship Students | B9: Option 1 tracker: students who need funding, their grade, income group and field, and how far they have got.
A10: 2 Interests | B10: Option 2, Interest-based: the interests a student can pick.
A11: 2 Courses | B11: Option 2: every course, its level and length, and which interests it matches.
A12: 2 Interest Students | B12: Option 2 tracker: students who know what they enjoy, the interests they picked, and the course they chose.
A13: 3 Hazed Questions | B13: Option 3, Hazed-based (unsure students): the 5 guided questions, each answer, and the points it gives each field.
A14: 3 Hazed Students | B14: Option 3 tracker: students who are unsure, their 5 answers, the fields suggested, and the counsellor's follow-up.
A15: Lists | B15: Dropdown values (status, grade, income group and so on). Edit here to change the dropdowns.
A17: Legend
A18: Blue text | B18: Sample data copied from the website. Replace it with real information.
A19: Yellow cells | B19: Columns you fill in for each student.
A20: Grey cells | B20: Formulas that fill in by themselves. Do not type over them.
A21: Row 2 in each tracker | B21: An example student showing the expected format. Delete it when you add real students.
A23: Statuses | B23: New > Contacted > Consultation booked > Applying > Offer received > Registered (or Not proceeding).
A24: Open in Google Sheets | B24: Upload this file to Google Drive, then right-click it and choose Open with > Google Sheets. To keep a pure Google copy, use File > Save as Google Sheets.

Sheet Fields
A1: Field ID | B1: Field name | C1: Description (optional)
A2: med | B2: Medicine & Health
A3: eng | B3: Engineering
A4: cs | B4: Computer Science & IT
A5: biz | B5: Business & Finance
A6: design | B6: Design & Creative Arts
A7: law | B7: Law
A8: edu | B8: Education
A9: sci | B9: Science
A10: hosp | B10: Hospitality & Tourism
A11: comm | B11: Communication & Media

Sheet Universities
A1: University ID | B1: Name | C1: City / State | D1: Fields offered (Field IDs, comma separated) | E1: Hostel / accommodation | F1: Hostel rent (RM / month, shared room) | G1: Website | H1: Admissions contact | I1: Phone / email | J1: Notes
A2: a | B2: Sample University A | C2: Kuala Lumpur | D2: med, sci, biz | E2: On-campus hostel | F2: 450
A3: b | B3: Sample University B | C3: Penang | D3: eng, cs, sci | E3: On-campus hostel | F3: 380
A4: c | B4: Sample College C | C4: Johor Bahru | D4: biz, hosp, comm | E4: Partner hostel, 10 minutes by shuttle | F4: 520
A5: d | B5: Sample University D | C5: Selangor | D5: design, comm, cs | E5: On-campus hostel | F5: 480
A6: e | B6: Sample College E | C6: Kuching | D6: edu, biz, hosp | E6: On-campus hostel | F6: 300
A7: f | B7: Sample University F | C7: Kuala Lumpur | D7: law, biz, edu | E7: No hostel. Eduplan helps find a rented room nearby

Sheet 1 Scholarships
A1: Scholarship ID | B1: Scholarship name | C1: University ID | D1: University name | E1: Type | F1: Tuition covered (%) | G1: Minimum grade (A/B/C) | H1: Income groups allowed (blank = any) | I1: Fields allowed (Field IDs, blank = any) | J1: Needs sports / co-curricular? | K1: Other requirements | L1: Application deadline | M1: How to apply (link) | N1: Bond / conditions | O1: Notes | P1: Fields covered (auto: fields allowed, or else the fields its university offers)
A2: S1 | B2: Merit Scholarship | C2: a | D2: =IF(C2="","",IFERROR(INDEX(Universities!$B$2:$B$100,MATCH(C2,Universities!$A$2:$A$100,0)),"Unknown ID")) -> Sample University A | E2: Merit | F2: 1 | G2: A | J2: No | P2: =IF(A2="","",IF(I2<>"",I2,IFERROR(INDEX(Universities!$D$2:$D$100,MATCH(C2,Universities!$A$2:$A$100,0)),""))) -> med, sci, biz
A3: S2 | B3: High Achiever Award | C3: b | D3: =IF(C3="","",IFERROR(INDEX(Universities!$B$2:$B$100,MATCH(C3,Universities!$A$2:$A$100,0)),"Unknown ID")) -> Sample University B | E3: Merit | F3: 0.5 | G3: A | J3: No | P3: =IF(A3="","",IF(I3<>"",I3,IFERROR(INDEX(Universities!$D$2:$D$100,MATCH(C3,Universities!$A$2:$A$100,0)),""))) -> eng, cs, sci
A4: S3 | B4: Bursary for B40 Families | C4: c | D4: =IF(C4="","",IFERROR(INDEX(Universities!$B$2:$B$100,MATCH(C4,Universities!$A$2:$A$100,0)),"Unknown ID")) -> Sample College C | E4: Need-based | F4: 0.7 | G4: C | H4: B40 | J4: No | P4: =IF(A4="","",IF(I4<>"",I4,IFERROR(INDEX(Universities!$D$2:$D$100,MATCH(C4,Universities!$A$2:$A$100,0)),""))) -> biz, hosp, comm
A5: S4 | B5: Need-based Grant | C5: d | D5: =IF(C5="","",IFERROR(INDEX(Universities!$B$2:$B$100,MATCH(C5,Universities!$A$2:$A$100,0)),"Unknown ID")) -> Sample University D | E5: Need-based | F5: 0.4 | G5: B | H5: B40, M40 | J5: No | P5: =IF(A5="","",IF(I5<>"",I5,IFERROR(INDEX(Universities!$D$2:$D$100,MATCH(C5,Universities!$A$2:$A$100,0)),""))) -> design, comm, cs
A6: S5 | B6: Engineering Talent Scholarship | C6: b | D6: =IF(C6="","",IFERROR(INDEX(Universities!$B$2:$B$100,MATCH(C6,Universities!$A$2:$A$100,0)),"Unknown ID")) -> Sample University B | E6: Field-specific | F6: 0.6 | G6: B | I6: eng | J6: No | P6: =IF(A6="","",IF(I6<>"",I6,IFERROR(INDEX(Universities!$D$2:$D$100,MATCH(C6,Universities!$A$2:$A$100,0)),""))) -> eng
A7: S6 | B7: Future Teachers Award | C7: e | D7: =IF(C7="","",IFERROR(INDEX(Universities!$B$2:$B$100,MATCH(C7,Universities!$A$2:$A$100,0)),"Unknown ID")) -> Sample College E | E7: Field-specific | F7: 0.5 | G7: B | I7: edu | J7: No | P7: =IF(A7="","",IF(I7<>"",I7,IFERROR(INDEX(Universities!$D$2:$D$100,MATCH(C7,Universities!$A$2:$A$100,0)),""))) -> edu
A8: S7 | B8: Sports and Co-curricular Award | C8: f | D8: =IF(C8="","",IFERROR(INDEX(Universities!$B$2:$B$100,MATCH(C8,Universities!$A$2:$A$100,0)),"Unknown ID")) -> Sample University F | E8: Sports & co-curricular | F8: 0.3 | G8: C | J8: Yes | P8: =IF(A8="","",IF(I8<>"",I8,IFERROR(INDEX(Universities!$D$2:$D$100,MATCH(C8,Universities!$A$2:$A$100,0)),""))) -> law, biz, edu
A9: S8 | B9: Early Bird Tuition Waiver | C9: c | D9: =IF(C9="","",IFERROR(INDEX(Universities!$B$2:$B$100,MATCH(C9,Universities!$A$2:$A$100,0)),"Unknown ID")) -> Sample College C | E9: Tuition waiver | F9: 0.2 | G9: C | J9: No | P9: =IF(A9="","",IF(I9<>"",I9,IFERROR(INDEX(Universities!$D$2:$D$100,MATCH(C9,Universities!$A$2:$A$100,0)),""))) -> biz, hosp, comm
D10: =IF(C10="","",IFERROR(INDEX(Universities!$B$2:$B$100,MATCH(C10,Universities!$A$2:$A$100,0)),"Unknown ID")) | P10: =IF(A10="","",IF(I10<>"",I10,IFERROR(INDEX(Universities!$D$2:$D$100,MATCH(C10,Universities!$A$2:$A$100,0)),"")))
D11: =IF(C11="","",IFERROR(INDEX(Universities!$B$2:$B$100,MATCH(C11,Universities!$A$2:$A$100,0)),"Unknown ID")) | P11: =IF(A11="","",IF(I11<>"",I11,IFERROR(INDEX(Universities!$D$2:$D$100,MATCH(C11,Universities!$A$2:$A$100,0)),"")))
D12: =IF(C12="","",IFERROR(INDEX(Universities!$B$2:$B$100,MATCH(C12,Universities!$A$2:$A$100,0)),"Unknown ID")) | P12: =IF(A12="","",IF(I12<>"",I12,IFERROR(INDEX(Universities!$D$2:$D$100,MATCH(C12,Universities!$A$2:$A$100,0)),"")))
D13: =IF(C13="","",IFERROR(INDEX(Universities!$B$2:$B$100,MATCH(C13,Universities!$A$2:$A$100,0)),"Unknown ID")) | P13: =IF(A13="","",IF(I13<>"",I13,IFERROR(INDEX(Universities!$D$2:$D$100,MATCH(C13,Universities!$A$2:$A$100,0)),"")))
D14: =IF(C14="","",IFERROR(INDEX(Universities!$B$2:$B$100,MATCH(C14,Universities!$A$2:$A$100,0)),"Unknown ID")) | P14: =IF(A14="","",IF(I14<>"",I14,IFERROR(INDEX(Universities!$D$2:$D$100,MATCH(C14,Universities!$A$2:$A$100,0)),"")))
D15: =IF(C15="","",IFERROR(INDEX(Universities!$B$2:$B$100,MATCH(C15,Universities!$A$2:$A$100,0)),"Unknown ID")) | P15: =IF(A15="","",IF(I15<>"",I15,IFERROR(INDEX(Universities!$D$2:$D$100,MATCH(C15,Universities!$A$2:$A$100,0)),"")))
D16: =IF(C16="","",IFERROR(INDEX(Universities!$B$2:$B$100,MATCH(C16,Universities!$A$2:$A$100,0)),"Unknown ID")) | P16: =IF(A16="","",IF(I16<>"",I16,IFERROR(INDEX(Universities!$D$2:$D$100,MATCH(C16,Universities!$A$2:$A$100,0)),"")))
D17: =IF(C17="","",IFERROR(INDEX(Universities!$B$2:$B$100,MATCH(C17,Universities!$A$2:$A$100,0)),"Unknown ID")) | P17: =IF(A17="","",IF(I17<>"",I17,IFERROR(INDEX(Universities!$D$2:$D$100,MATCH(C17,Universities!$A$2:$A$100,0)),"")))
D18: =IF(C18="","",IFERROR(INDEX(Universities!$B$2:$B$100,MATCH(C18,Universities!$A$2:$A$100,0)),"Unknown ID")) | P18: =IF(A18="","",IF(I18<>"",I18,IFERROR(INDEX(Universities!$D$2:$D$100,MATCH(C18,Universities!$A$2:$A$100,0)),"")))
D19: =IF(C19="","",IFERROR(INDEX(Universities!$B$2:$B$100,MATCH(C19,Universities!$A$2:$A$100,0)),"Unknown ID")) | P19: =IF(A19="","",IF(I19<>"",I19,IFERROR(INDEX(Universities!$D$2:$D$100,MATCH(C19,Universities!$A$2:$A$100,0)),"")))
D20: =IF(C20="","",IFERROR(INDEX(Universities!$B$2:$B$100,MATCH(C20,Universities!$A$2:$A$100,0)),"Unknown ID")) | P20: =IF(A20="","",IF(I20<>"",I20,IFERROR(INDEX(Universities!$D$2:$D$100,MATCH(C20,Universities!$A$2:$A$100,0)),"")))
D21: =IF(C21="","",IFERROR(INDEX(Universities!$B$2:$B$100,MATCH(C21,Universities!$A$2:$A$100,0)),"Unknown ID")) | P21: =IF(A21="","",IF(I21<>"",I21,IFERROR(INDEX(Universities!$D$2:$D$100,MATCH(C21,Universities!$A$2:$A$100,0)),"")))
... D60: =IF(C60="","",IFERROR(INDEX(Universities!$B$2:$B$100,MATCH(C60,Universities!$A$2:$A$100,0)),"Unknown ID")) | P60: =IF(A60="","",IF(I60<>"",I60,IFERROR(INDEX(Universities!$D$2:$D$100,MATCH(C60,Universities!$A$2:$A$100,0)),"")))

Sheet 1 Scholarship Students
A1: Student ID | B1: Date enquired | C1: Full name | D1: Phone / WhatsApp | E1: Email | F1: Latest qualification | G1: School / state | H1: How they found us | I1: Average grade (A/B/C) | J1: Household income group | K1: Field wanted (Field ID) | L1: Sports / co-curricular rep? | M1: Number of matching scholarships | N1: Best coverage available | O1: Scholarships shortlisted | P1: Counsellor | Q1: Status | R1: Next follow-up date | S1: Consultation date | T1: Final course | U1: Final university | V1: Notes
A2: ST-001 | B2: 46303 | C2: Nur Aisyah binti Ahmad | D2: 012-345 6789 | E2: aisyah@example.com | F2: SPM | G2: SMK Example, Selangor | H2: Website | I2: B | J2: B40 | K2: eng | L2: No | M2: =IF(OR(I2="",J2=""),"",SUMPRODUCT((CODE(I2)<=CODE('1 Scholarships'!$G$2:$G$60))*('1 Scholarships'!$A$2:$A$60<>"")*(('1 Scholarships'!$H$2:$H$60="")+ISNUMBER(SEARCH(","&J2&",",","&SUBSTITUTE('1 Scholarships'!$H$2:$H$60," ","")&","))>0)*(('1 Scholarships'!$J$2:$J$60<>"Yes")+(L2="Yes")>0)*((K2="")+ISNUMBER(SEARCH(","&K2&",",","&SUBSTITUTE('1 Scholarships'!$P$2:$P$60," ","")&","))>0))) -> 1 | N2: =IF(OR(I2="",J2=""),"",SUMPRODUCT(MAX((CODE(I2)<=CODE('1 Scholarships'!$G$2:$G$60))*('1 Scholarships'!$A$2:$A$60<>"")*(('1 Scholarships'!$H$2:$H$60="")+ISNUMBER(SEARCH(","&J2&",",","&SUBSTITUTE('1 Scholarships'!$H$2:$H$60," ","")&","))>0)*(('1 Scholarships'!$J$2:$J$60<>"Yes")+(L2="Yes")>0)*((K2="")+ISNUMBER(SEARCH(","&K2&",",","&SUBSTITUTE('1 Scholarships'!$P$2:$P$60," ","")&","))>0)*'1 Scholarships'!$F$2:$F$60))) -> 0.6 | O2: Engineering Talent Scholarship | P2: Mei Ling | Q2: Contacted | R2: 46310
M3: =IF(OR(I3="",J3=""),"",SUMPRODUCT((CODE(I3)<=CODE('1 Scholarships'!$G$2:$G$60))*('1 Scholarships'!$A$2:$A$60<>"")*(('1 Scholarships'!$H$2:$H$60="")+ISNUMBER(SEARCH(","&J3&",",","&SUBSTITUTE('1 Scholarships'!$H$2:$H$60," ","")&","))>0)*(('1 Scholarships'!$J$2:$J$60<>"Yes")+(L3="Yes")>0)*((K3="")+ISNUMBER(SEARCH(","&K3&",",","&SUBSTITUTE('1 Scholarships'!$P$2:$P$60," ","")&","))>0))) | N3: =IF(OR(I3="",J3=""),"",SUMPRODUCT(MAX((CODE(I3)<=CODE('1 Scholarships'!$G$2:$G$60))*('1 Scholarships'!$A$2:$A$60<>"")*(('1 Scholarships'!$H$2:$H$60="")+ISNUMBER(SEARCH(","&J3&",",","&SUBSTITUTE('1 Scholarships'!$H$2:$H$60," ","")&","))>0)*(('1 Scholarships'!$J$2:$J$60<>"Yes")+(L3="Yes")>0)*((K3="")+ISNUMBER(SEARCH(","&K3&",",","&SUBSTITUTE('1 Scholarships'!$P$2:$P$60," ","")&","))>0)*'1 Scholarships'!$F$2:$F$60)))
M4: =IF(OR(I4="",J4=""),"",SUMPRODUCT((CODE(I4)<=CODE('1 Scholarships'!$G$2:$G$60))*('1 Scholarships'!$A$2:$A$60<>"")*(('1 Scholarships'!$H$2:$H$60="")+ISNUMBER(SEARCH(","&J4&",",","&SUBSTITUTE('1 Scholarships'!$H$2:$H$60," ","")&","))>0)*(('1 Scholarships'!$J$2:$J$60<>"Yes")+(L4="Yes")>0)*((K4="")+ISNUMBER(SEARCH(","&K4&",",","&SUBSTITUTE('1 Scholarships'!$P$2:$P$60," ","")&","))>0))) | N4: =IF(OR(I4="",J4=""),"",SUMPRODUCT(MAX((CODE(I4)<=CODE('1 Scholarships'!$G$2:$G$60))*('1 Scholarships'!$A$2:$A$60<>"")*(('1 Scholarships'!$H$2:$H$60="")+ISNUMBER(SEARCH(","&J4&",",","&SUBSTITUTE('1 Scholarships'!$H$2:$H$60," ","")&","))>0)*(('1 Scholarships'!$J$2:$J$60<>"Yes")+(L4="Yes")>0)*((K4="")+ISNUMBER(SEARCH(","&K4&",",","&SUBSTITUTE('1 Scholarships'!$P$2:$P$60," ","")&","))>0)*'1 Scholarships'!$F$2:$F$60)))
M5: =IF(OR(I5="",J5=""),"",SUMPRODUCT((CODE(I5)<=CODE('1 Scholarships'!$G$2:$G$60))*('1 Scholarships'!$A$2:$A$60<>"")*(('1 Scholarships'!$H$2:$H$60="")+ISNUMBER(SEARCH(","&J5&",",","&SUBSTITUTE('1 Scholarships'!$H$2:$H$60," ","")&","))>0)*(('1 Scholarships'!$J$2:$J$60<>"Yes")+(L5="Yes")>0)*((K5="")+ISNUMBER(SEARCH(","&K5&",",","&SUBSTITUTE('1 Scholarships'!$P$2:$P$60," ","")&","))>0))) | N5: =IF(OR(I5="",J5=""),"",SUMPRODUCT(MAX((CODE(I5)<=CODE('1 Scholarships'!$G$2:$G$60))*('1 Scholarships'!$A$2:$A$60<>"")*(('1 Scholarships'!$H$2:$H$60="")+ISNUMBER(SEARCH(","&J5&",",","&SUBSTITUTE('1 Scholarships'!$H$2:$H$60," ","")&","))>0)*(('1 Scholarships'!$J$2:$J$60<>"Yes")+(L5="Yes")>0)*((K5="")+ISNUMBER(SEARCH(","&K5&",",","&SUBSTITUTE('1 Scholarships'!$P$2:$P$60," ","")&","))>0)*'1 Scholarships'!$F$2:$F$60)))
M6: =IF(OR(I6="",J6=""),"",SUMPRODUCT((CODE(I6)<=CODE('1 Scholarships'!$G$2:$G$60))*('1 Scholarships'!$A$2:$A$60<>"")*(('1 Scholarships'!$H$2:$H$60="")+ISNUMBER(SEARCH(","&J6&",",","&SUBSTITUTE('1 Scholarships'!$H$2:$H$60," ","")&","))>0)*(('1 Scholarships'!$J$2:$J$60<>"Yes")+(L6="Yes")>0)*((K6="")+ISNUMBER(SEARCH(","&K6&",",","&SUBSTITUTE('1 Scholarships'!$P$2:$P$60," ","")&","))>0))) | N6: =IF(OR(I6="",J6=""),"",SUMPRODUCT(MAX((CODE(I6)<=CODE('1 Scholarships'!$G$2:$G$60))*('1 Scholarships'!$A$2:$A$60<>"")*(('1 Scholarships'!$H$2:$H$60="")+ISNUMBER(SEARCH(","&J6&",",","&SUBSTITUTE('1 Scholarships'!$H$2:$H$60," ","")&","))>0)*(('1 Scholarships'!$J$2:$J$60<>"Yes")+(L6="Yes")>0)*((K6="")+ISNUMBER(SEARCH(","&K6&",",","&SUBSTITUTE('1 Scholarships'!$P$2:$P$60," ","")&","))>0)*'1 Scholarships'!$F$2:$F$60)))
M7: =IF(OR(I7="",J7=""),"",SUMPRODUCT((CODE(I7)<=CODE('1 Scholarships'!$G$2:$G$60))*('1 Scholarships'!$A$2:$A$60<>"")*(('1 Scholarships'!$H$2:$H$60="")+ISNUMBER(SEARCH(","&J7&",",","&SUBSTITUTE('1 Scholarships'!$H$2:$H$60," ","")&","))>0)*(('1 Scholarships'!$J$2:$J$60<>"Yes")+(L7="Yes")>0)*((K7="")+ISNUMBER(SEARCH(","&K7&",",","&SUBSTITUTE('1 Scholarships'!$P$2:$P$60," ","")&","))>0))) | N7: =IF(OR(I7="",J7=""),"",SUMPRODUCT(MAX((CODE(I7)<=CODE('1 Scholarships'!$G$2:$G$60))*('1 Scholarships'!$A$2:$A$60<>"")*(('1 Scholarships'!$H$2:$H$60="")+ISNUMBER(SEARCH(","&J7&",",","&SUBSTITUTE('1 Scholarships'!$H$2:$H$60," ","")&","))>0)*(('1 Scholarships'!$J$2:$J$60<>"Yes")+(L7="Yes")>0)*((K7="")+ISNUMBER(SEARCH(","&K7&",",","&SUBSTITUTE('1 Scholarships'!$P$2:$P$60," ","")&","))>0)*'1 Scholarships'!$F$2:$F$60)))
M8: =IF(OR(I8="",J8=""),"",SUMPRODUCT((CODE(I8)<=CODE('1 Scholarships'!$G$2:$G$60))*('1 Scholarships'!$A$2:$A$60<>"")*(('1 Scholarships'!$H$2:$H$60="")+ISNUMBER(SEARCH(","&J8&",",","&SUBSTITUTE('1 Scholarships'!$H$2:$H$60," ","")&","))>0)*(('1 Scholarships'!$J$2:$J$60<>"Yes")+(L8="Yes")>0)*((K8="")+ISNUMBER(SEARCH(","&K8&",",","&SUBSTITUTE('1 Scholarships'!$P$2:$P$60," ","")&","))>0))) | N8: =IF(OR(I8="",J8=""),"",SUMPRODUCT(MAX((CODE(I8)<=CODE('1 Scholarships'!$G$2:$G$60))*('1 Scholarships'!$A$2:$A$60<>"")*(('1 Scholarships'!$H$2:$H$60="")+ISNUMBER(SEARCH(","&J8&",",","&SUBSTITUTE('1 Scholarships'!$H$2:$H$60," ","")&","))>0)*(('1 Scholarships'!$J$2:$J$60<>"Yes")+(L8="Yes")>0)*((K8="")+ISNUMBER(SEARCH(","&K8&",",","&SUBSTITUTE('1 Scholarships'!$P$2:$P$60," ","")&","))>0)*'1 Scholarships'!$F$2:$F$60)))
M9: =IF(OR(I9="",J9=""),"",SUMPRODUCT((CODE(I9)<=CODE('1 Scholarships'!$G$2:$G$60))*('1 Scholarships'!$A$2:$A$60<>"")*(('1 Scholarships'!$H$2:$H$60="")+ISNUMBER(SEARCH(","&J9&",",","&SUBSTITUTE('1 Scholarships'!$H$2:$H$60," ","")&","))>0)*(('1 Scholarships'!$J$2:$J$60<>"Yes")+(L9="Yes")>0)*((K9="")+ISNUMBER(SEARCH(","&K9&",",","&SUBSTITUTE('1 Scholarships'!$P$2:$P$60," ","")&","))>0))) | N9: =IF(OR(I9="",J9=""),"",SUMPRODUCT(MAX((CODE(I9)<=CODE('1 Scholarships'!$G$2:$G$60))*('1 Scholarships'!$A$2:$A$60<>"")*(('1 Scholarships'!$H$2:$H$60="")+ISNUMBER(SEARCH(","&J9&",",","&SUBSTITUTE('1 Scholarships'!$H$2:$H$60," ","")&","))>0)*(('1 Scholarships'!$J$2:$J$60<>"Yes")+(L9="Yes")>0)*((K9="")+ISNUMBER(SEARCH(","&K9&",",","&SUBSTITUTE('1 Scholarships'!$P$2:$P$60," ","")&","))>0)*'1 Scholarships'!$F$2:$F$60)))
M10: =IF(OR(I10="",J10=""),"",SUMPRODUCT((CODE(I10)<=CODE('1 Scholarships'!$G$2:$G$60))*('1 Scholarships'!$A$2:$A$60<>"")*(('1 Scholarships'!$H$2:$H$60="")+ISNUMBER(SEARCH(","&J10&",",","&SUBSTITUTE('1 Scholarships'!$H$2:$H$60," ","")&","))>0)*(('1 Scholarships'!$J$2:$J$60<>"Yes")+(L10="Yes")>0)*((K10="")+ISNUMBER(SEARCH(","&K10&",",","&SUBSTITUTE('1 Scholarships'!$P$2:$P$60," ","")&","))>0))) | N10: =IF(OR(I10="",J10=""),"",SUMPRODUCT(MAX((CODE(I10)<=CODE('1 Scholarships'!$G$2:$G$60))*('1 Scholarships'!$A$2:$A$60<>"")*(('1 Scholarships'!$H$2:$H$60="")+ISNUMBER(SEARCH(","&J10&",",","&SUBSTITUTE('1 Scholarships'!$H$2:$H$60," ","")&","))>0)*(('1 Scholarships'!$J$2:$J$60<>"Yes")+(L10="Yes")>0)*((K10="")+ISNUMBER(SEARCH(","&K10&",",","&SUBSTITUTE('1 Scholarships'!$P$2:$P$60," ","")&","))>0)*'1 Scholarships'!$F$2:$F$60)))
M11: =IF(OR(I11="",J11=""),"",SUMPRODUCT((CODE(I11)<=CODE('1 Scholarships'!$G$2:$G$60))*('1 Scholarships'!$A$2:$A$60<>"")*(('1 Scholarships'!$H$2:$H$60="")+ISNUMBER(SEARCH(","&J11&",",","&SUBSTITUTE('1 Scholarships'!$H$2:$H$60," ","")&","))>0)*(('1 Scholarships'!$J$2:$J$60<>"Yes")+(L11="Yes")>0)*((K11="")+ISNUMBER(SEARCH(","&K11&",",","&SUBSTITUTE('1 Scholarships'!$P$2:$P$60," ","")&","))>0))) | N11: =IF(OR(I11="",J11=""),"",SUMPRODUCT(MAX((CODE(I11)<=CODE('1 Scholarships'!$G$2:$G$60))*('1 Scholarships'!$A$2:$A$60<>"")*(('1 Scholarships'!$H$2:$H$60="")+ISNUMBER(SEARCH(","&J11&",",","&SUBSTITUTE('1 Scholarships'!$H$2:$H$60," ","")&","))>0)*(('1 Scholarships'!$J$2:$J$60<>"Yes")+(L11="Yes")>0)*((K11="")+ISNUMBER(SEARCH(","&K11&",",","&SUBSTITUTE('1 Scholarships'!$P$2:$P$60," ","")&","))>0)*'1 Scholarships'!$F$2:$F$60)))
M12: =IF(OR(I12="",J12=""),"",SUMPRODUCT((CODE(I12)<=CODE('1 Scholarships'!$G$2:$G$60))*('1 Scholarships'!$A$2:$A$60<>"")*(('1 Scholarships'!$H$2:$H$60="")+ISNUMBER(SEARCH(","&J12&",",","&SUBSTITUTE('1 Scholarships'!$H$2:$H$60," ","")&","))>0)*(('1 Scholarships'!$J$2:$J$60<>"Yes")+(L12="Yes")>0)*((K12="")+ISNUMBER(SEARCH(","&K12&",",","&SUBSTITUTE('1 Scholarships'!$P$2:$P$60," ","")&","))>0))) | N12: =IF(OR(I12="",J12=""),"",SUMPRODUCT(MAX((CODE(I12)<=CODE('1 Scholarships'!$G$2:$G$60))*('1 Scholarships'!$A$2:$A$60<>"")*(('1 Scholarships'!$H$2:$H$60="")+ISNUMBER(SEARCH(","&J12&",",","&SUBSTITUTE('1 Scholarships'!$H$2:$H$60," ","")&","))>0)*(('1 Scholarships'!$J$2:$J$60<>"Yes")+(L12="Yes")>0)*((K12="")+ISNUMBER(SEARCH(","&K12&",",","&SUBSTITUTE('1 Scholarships'!$P$2:$P$60," ","")&","))>0)*'1 Scholarships'!$F$2:$F$60)))
M13: =IF(OR(I13="",J13=""),"",SUMPRODUCT((CODE(I13)<=CODE('1 Scholarships'!$G$2:$G$60))*('1 Scholarships'!$A$2:$A$60<>"")*(('1 Scholarships'!$H$2:$H$60="")+ISNUMBER(SEARCH(","&J13&",",","&SUBSTITUTE('1 Scholarships'!$H$2:$H$60," ","")&","))>0)*(('1 Scholarships'!$J$2:$J$60<>"Yes")+(L13="Yes")>0)*((K13="")+ISNUMBER(SEARCH(","&K13&",",","&SUBSTITUTE('1 Scholarships'!$P$2:$P$60," ","")&","))>0))) | N13: =IF(OR(I13="",J13=""),"",SUMPRODUCT(MAX((CODE(I13)<=CODE('1 Scholarships'!$G$2:$G$60))*('1 Scholarships'!$A$2:$A$60<>"")*(('1 Scholarships'!$H$2:$H$60="")+ISNUMBER(SEARCH(","&J13&",",","&SUBSTITUTE('1 Scholarships'!$H$2:$H$60," ","")&","))>0)*(('1 Scholarships'!$J$2:$J$60<>"Yes")+(L13="Yes")>0)*((K13="")+ISNUMBER(SEARCH(","&K13&",",","&SUBSTITUTE('1 Scholarships'!$P$2:$P$60," ","")&","))>0)*'1 Scholarships'!$F$2:$F$60)))
M14: =IF(OR(I14="",J14=""),"",SUMPRODUCT((CODE(I14)<=CODE('1 Scholarships'!$G$2:$G$60))*('1 Scholarships'!$A$2:$A$60<>"")*(('1 Scholarships'!$H$2:$H$60="")+ISNUMBER(SEARCH(","&J14&",",","&SUBSTITUTE('1 Scholarships'!$H$2:$H$60," ","")&","))>0)*(('1 Scholarships'!$J$2:$J$60<>"Yes")+(L14="Yes")>0)*((K14="")+ISNUMBER(SEARCH(","&K14&",",","&SUBSTITUTE('1 Scholarships'!$P$2:$P$60," ","")&","))>0))) | N14: =IF(OR(I14="",J14=""),"",SUMPRODUCT(MAX((CODE(I14)<=CODE('1 Scholarships'!$G$2:$G$60))*('1 Scholarships'!$A$2:$A$60<>"")*(('1 Scholarships'!$H$2:$H$60="")+ISNUMBER(SEARCH(","&J14&",",","&SUBSTITUTE('1 Scholarships'!$H$2:$H$60," ","")&","))>0)*(('1 Scholarships'!$J$2:$J$60<>"Yes")+(L14="Yes")>0)*((K14="")+ISNUMBER(SEARCH(","&K14&",",","&SUBSTITUTE('1 Scholarships'!$P$2:$P$60," ","")&","))>0)*'1 Scholarships'!$F$2:$F$60)))
... M300: =IF(OR(I300="",J300=""),"",SUMPRODUCT((CODE(I300)<=CODE('1 Scholarships'!$G$2:$G$60))*('1 Scholarships'!$A$2:$A$60<>"")*(('1 Scholarships'!$H$2:$H$60="")+ISNUMBER(SEARCH(","&J300&",",","&SUBSTITUTE('1 Scholarships'!$H$2:$H$60," ","")&","))>0)*(('1 Scholarships'!$J$2:$J$60<>"Yes")+(L300="Yes")>0)*((K300="")+ISNUMBER(SEARCH(","&K300&",",","&SUBSTITUTE('1 Scholarships'!$P$2:$P$60," ","")&","))>0))) | N300: =IF(OR(I300="",J300=""),"",SUMPRODUCT(MAX((CODE(I300)<=CODE('1 Scholarships'!$G$2:$G$60))*('1 Scholarships'!$A$2:$A$60<>"")*(('1 Scholarships'!$H$2:$H$60="")+ISNUMBER(SEARCH(","&J300&",",","&SUBSTITUTE('1 Scholarships'!$H$2:$H$60," ","")&","))>0)*(('1 Scholarships'!$J$2:$J$60<>"Yes")+(L300="Yes")>0)*((K300="")+ISNUMBER(SEARCH(","&K300&",",","&SUBSTITUTE('1 Scholarships'!$P$2:$P$60," ","")&","))>0)*'1 Scholarships'!$F$2:$F$60)))

Sheet 2 Interests
A1: Interest ID | B1: Interest (as students see it) | C1: Notes
A2: help | B2: Helping people
A3: build | B3: Building and fixing things
A4: computers | B4: Computers and coding
A5: numbers | B5: Numbers and money
A6: design | B6: Drawing and design
A7: argue | B7: Debating and arguing a case
A8: teach | B8: Teaching and explaining
A9: experiments | B9: Experiments and discovery
A10: travel | B10: Food, travel and hosting
A11: lead | B11: Leading and organising
A12: write | B12: Writing and storytelling

Sheet 2 Courses
A1: Course ID | B1: Course name | C1: Field ID | D1: Field name | E1: Level | F1: Duration (years) | G1: Interest 1 | H1: Interest 2 | I1: Interest 3 | J1: Offered at (University IDs, comma separated) | K1: Intakes | L1: Entry requirements | M1: Tuition fee (RM, whole course) | N1: Notes
A2: C01 | B2: Bachelor of Medicine and Surgery (MBBS) | C2: med | D2: =IF(C2="","",IFERROR(INDEX(Fields!$B$2:$B$50,MATCH(C2,Fields!$A$2:$A$50,0)),"Unknown ID")) -> Medicine & Health | E2: Degree | F2: 5 | G2: help | H2: experiments | J2: a
A3: C02 | B3: Diploma in Nursing | C3: med | D3: =IF(C3="","",IFERROR(INDEX(Fields!$B$2:$B$50,MATCH(C3,Fields!$A$2:$A$50,0)),"Unknown ID")) -> Medicine & Health | E3: Diploma | F3: 3 | G3: help | J3: a
A4: C03 | B4: Bachelor of Pharmacy | C4: med | D4: =IF(C4="","",IFERROR(INDEX(Fields!$B$2:$B$50,MATCH(C4,Fields!$A$2:$A$50,0)),"Unknown ID")) -> Medicine & Health | E4: Degree | F4: 4 | G4: experiments | H4: help | J4: a
A5: C04 | B5: Bachelor of Civil Engineering | C5: eng | D5: =IF(C5="","",IFERROR(INDEX(Fields!$B$2:$B$50,MATCH(C5,Fields!$A$2:$A$50,0)),"Unknown ID")) -> Engineering | E5: Degree | F5: 4 | G5: build | H5: numbers | J5: b
A6: C05 | B6: Diploma in Mechanical Engineering | C6: eng | D6: =IF(C6="","",IFERROR(INDEX(Fields!$B$2:$B$50,MATCH(C6,Fields!$A$2:$A$50,0)),"Unknown ID")) -> Engineering | E6: Diploma | F6: 2.5 | G6: build | J6: b
A7: C06 | B7: Bachelor of Computer Science | C7: cs | D7: =IF(C7="","",IFERROR(INDEX(Fields!$B$2:$B$50,MATCH(C7,Fields!$A$2:$A$50,0)),"Unknown ID")) -> Computer Science & IT | E7: Degree | F7: 3 | G7: computers | H7: numbers | J7: b, d
A8: C07 | B8: Diploma in Information Technology | C8: cs | D8: =IF(C8="","",IFERROR(INDEX(Fields!$B$2:$B$50,MATCH(C8,Fields!$A$2:$A$50,0)),"Unknown ID")) -> Computer Science & IT | E8: Diploma | F8: 2 | G8: computers | J8: b, d
A9: C08 | B9: Bachelor of Accounting | C9: biz | D9: =IF(C9="","",IFERROR(INDEX(Fields!$B$2:$B$50,MATCH(C9,Fields!$A$2:$A$50,0)),"Unknown ID")) -> Business & Finance | E9: Degree | F9: 3 | G9: numbers | J9: a, c, e, f
A10: C09 | B10: Diploma in Business Administration | C10: biz | D10: =IF(C10="","",IFERROR(INDEX(Fields!$B$2:$B$50,MATCH(C10,Fields!$A$2:$A$50,0)),"Unknown ID")) -> Business & Finance | E10: Diploma | F10: 2 | G10: lead | H10: numbers | J10: a, c, e, f
A11: C10 | B11: Bachelor of Graphic Design | C11: design | D11: =IF(C11="","",IFERROR(INDEX(Fields!$B$2:$B$50,MATCH(C11,Fields!$A$2:$A$50,0)),"Unknown ID")) -> Design & Creative Arts | E11: Degree | F11: 3 | G11: design | J11: d
A12: C11 | B12: Diploma in Interior Design | C12: design | D12: =IF(C12="","",IFERROR(INDEX(Fields!$B$2:$B$50,MATCH(C12,Fields!$A$2:$A$50,0)),"Unknown ID")) -> Design & Creative Arts | E12: Diploma | F12: 2.5 | G12: design | H12: build | J12: d
A13: C12 | B13: Bachelor of Laws (LLB) | C13: law | D13: =IF(C13="","",IFERROR(INDEX(Fields!$B$2:$B$50,MATCH(C13,Fields!$A$2:$A$50,0)),"Unknown ID")) -> Law | E13: Degree | F13: 3 | G13: argue | H13: write | J13: f
A14: C13 | B14: Bachelor of Education (TESL) | C14: edu | D14: =IF(C14="","",IFERROR(INDEX(Fields!$B$2:$B$50,MATCH(C14,Fields!$A$2:$A$50,0)),"Unknown ID")) -> Education | E14: Degree | F14: 4 | G14: teach | H14: write | J14: e, f
A15: C14 | B15: Diploma in Early Childhood Education | C15: edu | D15: =IF(C15="","",IFERROR(INDEX(Fields!$B$2:$B$50,MATCH(C15,Fields!$A$2:$A$50,0)),"Unknown ID")) -> Education | E15: Diploma | F15: 2.5 | G15: teach | H15: help | J15: e, f
A16: C15 | B16: Bachelor of Biotechnology | C16: sci | D16: =IF(C16="","",IFERROR(INDEX(Fields!$B$2:$B$50,MATCH(C16,Fields!$A$2:$A$50,0)),"Unknown ID")) -> Science | E16: Degree | F16: 3 | G16: experiments | J16: a, b
A17: C16 | B17: Diploma in Hotel Management | C17: hosp | D17: =IF(C17="","",IFERROR(INDEX(Fields!$B$2:$B$50,MATCH(C17,Fields!$A$2:$A$50,0)),"Unknown ID")) -> Hospitality & Tourism | E17: Diploma | F17: 2 | G17: travel | H17: lead | J17: c, e
A18: C17 | B18: Bachelor of Culinary Arts | C18: hosp | D18: =IF(C18="","",IFERROR(INDEX(Fields!$B$2:$B$50,MATCH(C18,Fields!$A$2:$A$50,0)),"Unknown ID")) -> Hospitality & Tourism | E18: Degree | F18: 3 | G18: travel | H18: design | J18: c, e
A19: C18 | B19: Bachelor of Mass Communication | C19: comm | D19: =IF(C19="","",IFERROR(INDEX(Fields!$B$2:$B$50,MATCH(C19,Fields!$A$2:$A$50,0)),"Unknown ID")) -> Communication & Media | E19: Degree | F19: 3 | G19: write | H19: design | J19: c, d
D20: =IF(C20="","",IFERROR(INDEX(Fields!$B$2:$B$50,MATCH(C20,Fields!$A$2:$A$50,0)),"Unknown ID"))
D21: =IF(C21="","",IFERROR(INDEX(Fields!$B$2:$B$50,MATCH(C21,Fields!$A$2:$A$50,0)),"Unknown ID"))
D22: =IF(C22="","",IFERROR(INDEX(Fields!$B$2:$B$50,MATCH(C22,Fields!$A$2:$A$50,0)),"Unknown ID"))
D23: =IF(C23="","",IFERROR(INDEX(Fields!$B$2:$B$50,MATCH(C23,Fields!$A$2:$A$50,0)),"Unknown ID"))
D24: =IF(C24="","",IFERROR(INDEX(Fields!$B$2:$B$50,MATCH(C24,Fields!$A$2:$A$50,0)),"Unknown ID"))
D25: =IF(C25="","",IFERROR(INDEX(Fields!$B$2:$B$50,MATCH(C25,Fields!$A$2:$A$50,0)),"Unknown ID"))
D26: =IF(C26="","",IFERROR(INDEX(Fields!$B$2:$B$50,MATCH(C26,Fields!$A$2:$A$50,0)),"Unknown ID"))
D27: =IF(C27="","",IFERROR(INDEX(Fields!$B$2:$B$50,MATCH(C27,Fields!$A$2:$A$50,0)),"Unknown ID"))
D28: =IF(C28="","",IFERROR(INDEX(Fields!$B$2:$B$50,MATCH(C28,Fields!$A$2:$A$50,0)),"Unknown ID"))
D29: =IF(C29="","",IFERROR(INDEX(Fields!$B$2:$B$50,MATCH(C29,Fields!$A$2:$A$50,0)),"Unknown ID"))
D30: =IF(C30="","",IFERROR(INDEX(Fields!$B$2:$B$50,MATCH(C30,Fields!$A$2:$A$50,0)),"Unknown ID"))
D31: =IF(C31="","",IFERROR(INDEX(Fields!$B$2:$B$50,MATCH(C31,Fields!$A$2:$A$50,0)),"Unknown ID"))
... D200: =IF(C200="","",IFERROR(INDEX(Fields!$B$2:$B$50,MATCH(C200,Fields!$A$2:$A$50,0)),"Unknown ID"))

Sheet 2 Interest Students
A1: Student ID | B1: Date enquired | C1: Full name | D1: Phone / WhatsApp | E1: Email | F1: Latest qualification | G1: School / state | H1: How they found us | I1: Interest 1 | J1: Interest 2 | K1: Interest 3 | L1: Level preference | M1: Matching courses | N1: Shortlisted course ID | O1: Counsellor | P1: Status | Q1: Next follow-up date | R1: Consultation date | S1: Final course | T1: Final university | U1: Notes
A2: ST-002 | B2: 46303 | C2: Daniel Tan Wei Jie | D2: 011-2233 4455 | E2: daniel@example.com | F2: SPM | G2: SMK Example, Penang | H2: School talk | I2: computers | J2: numbers | L2: Degree | M2: =IF(COUNTA(I2:K2)=0,"",SUMPRODUCT((((COUNTIF(I2:K2,'2 Courses'!$G$2:$G$200)*('2 Courses'!$G$2:$G$200<>""))+(COUNTIF(I2:K2,'2 Courses'!$H$2:$H$200)*('2 Courses'!$H$2:$H$200<>""))+(COUNTIF(I2:K2,'2 Courses'!$I$2:$I$200)*('2 Courses'!$I$2:$I$200<>"")))>0)*((L2="")+(L2="Diploma or degree")+('2 Courses'!$E$2:$E$200=L2)>0))) -> 3 | N2: C06 | O2: Mei Ling | P2: Consultation booked | Q2: 46307 | R2: 46309 | S2: Bachelor of Computer Science | T2: Sample University B
M3: =IF(COUNTA(I3:K3)=0,"",SUMPRODUCT((((COUNTIF(I3:K3,'2 Courses'!$G$2:$G$200)*('2 Courses'!$G$2:$G$200<>""))+(COUNTIF(I3:K3,'2 Courses'!$H$2:$H$200)*('2 Courses'!$H$2:$H$200<>""))+(COUNTIF(I3:K3,'2 Courses'!$I$2:$I$200)*('2 Courses'!$I$2:$I$200<>"")))>0)*((L3="")+(L3="Diploma or degree")+('2 Courses'!$E$2:$E$200=L3)>0)))
M4: =IF(COUNTA(I4:K4)=0,"",SUMPRODUCT((((COUNTIF(I4:K4,'2 Courses'!$G$2:$G$200)*('2 Courses'!$G$2:$G$200<>""))+(COUNTIF(I4:K4,'2 Courses'!$H$2:$H$200)*('2 Courses'!$H$2:$H$200<>""))+(COUNTIF(I4:K4,'2 Courses'!$I$2:$I$200)*('2 Courses'!$I$2:$I$200<>"")))>0)*((L4="")+(L4="Diploma or degree")+('2 Courses'!$E$2:$E$200=L4)>0)))
M5: =IF(COUNTA(I5:K5)=0,"",SUMPRODUCT((((COUNTIF(I5:K5,'2 Courses'!$G$2:$G$200)*('2 Courses'!$G$2:$G$200<>""))+(COUNTIF(I5:K5,'2 Courses'!$H$2:$H$200)*('2 Courses'!$H$2:$H$200<>""))+(COUNTIF(I5:K5,'2 Courses'!$I$2:$I$200)*('2 Courses'!$I$2:$I$200<>"")))>0)*((L5="")+(L5="Diploma or degree")+('2 Courses'!$E$2:$E$200=L5)>0)))
M6: =IF(COUNTA(I6:K6)=0,"",SUMPRODUCT((((COUNTIF(I6:K6,'2 Courses'!$G$2:$G$200)*('2 Courses'!$G$2:$G$200<>""))+(COUNTIF(I6:K6,'2 Courses'!$H$2:$H$200)*('2 Courses'!$H$2:$H$200<>""))+(COUNTIF(I6:K6,'2 Courses'!$I$2:$I$200)*('2 Courses'!$I$2:$I$200<>"")))>0)*((L6="")+(L6="Diploma or degree")+('2 Courses'!$E$2:$E$200=L6)>0)))
M7: =IF(COUNTA(I7:K7)=0,"",SUMPRODUCT((((COUNTIF(I7:K7,'2 Courses'!$G$2:$G$200)*('2 Courses'!$G$2:$G$200<>""))+(COUNTIF(I7:K7,'2 Courses'!$H$2:$H$200)*('2 Courses'!$H$2:$H$200<>""))+(COUNTIF(I7:K7,'2 Courses'!$I$2:$I$200)*('2 Courses'!$I$2:$I$200<>"")))>0)*((L7="")+(L7="Diploma or degree")+('2 Courses'!$E$2:$E$200=L7)>0)))
M8: =IF(COUNTA(I8:K8)=0,"",SUMPRODUCT((((COUNTIF(I8:K8,'2 Courses'!$G$2:$G$200)*('2 Courses'!$G$2:$G$200<>""))+(COUNTIF(I8:K8,'2 Courses'!$H$2:$H$200)*('2 Courses'!$H$2:$H$200<>""))+(COUNTIF(I8:K8,'2 Courses'!$I$2:$I$200)*('2 Courses'!$I$2:$I$200<>"")))>0)*((L8="")+(L8="Diploma or degree")+('2 Courses'!$E$2:$E$200=L8)>0)))
M9: =IF(COUNTA(I9:K9)=0,"",SUMPRODUCT((((COUNTIF(I9:K9,'2 Courses'!$G$2:$G$200)*('2 Courses'!$G$2:$G$200<>""))+(COUNTIF(I9:K9,'2 Courses'!$H$2:$H$200)*('2 Courses'!$H$2:$H$200<>""))+(COUNTIF(I9:K9,'2 Courses'!$I$2:$I$200)*('2 Courses'!$I$2:$I$200<>"")))>0)*((L9="")+(L9="Diploma or degree")+('2 Courses'!$E$2:$E$200=L9)>0)))
M10: =IF(COUNTA(I10:K10)=0,"",SUMPRODUCT((((COUNTIF(I10:K10,'2 Courses'!$G$2:$G$200)*('2 Courses'!$G$2:$G$200<>""))+(COUNTIF(I10:K10,'2 Courses'!$H$2:$H$200)*('2 Courses'!$H$2:$H$200<>""))+(COUNTIF(I10:K10,'2 Courses'!$I$2:$I$200)*('2 Courses'!$I$2:$I$200<>"")))>0)*((L10="")+(L10="Diploma or degree")+('2 Courses'!$E$2:$E$200=L10)>0)))
M11: =IF(COUNTA(I11:K11)=0,"",SUMPRODUCT((((COUNTIF(I11:K11,'2 Courses'!$G$2:$G$200)*('2 Courses'!$G$2:$G$200<>""))+(COUNTIF(I11:K11,'2 Courses'!$H$2:$H$200)*('2 Courses'!$H$2:$H$200<>""))+(COUNTIF(I11:K11,'2 Courses'!$I$2:$I$200)*('2 Courses'!$I$2:$I$200<>"")))>0)*((L11="")+(L11="Diploma or degree")+('2 Courses'!$E$2:$E$200=L11)>0)))
M12: =IF(COUNTA(I12:K12)=0,"",SUMPRODUCT((((COUNTIF(I12:K12,'2 Courses'!$G$2:$G$200)*('2 Courses'!$G$2:$G$200<>""))+(COUNTIF(I12:K12,'2 Courses'!$H$2:$H$200)*('2 Courses'!$H$2:$H$200<>""))+(COUNTIF(I12:K12,'2 Courses'!$I$2:$I$200)*('2 Courses'!$I$2:$I$200<>"")))>0)*((L12="")+(L12="Diploma or degree")+('2 Courses'!$E$2:$E$200=L12)>0)))
M13: =IF(COUNTA(I13:K13)=0,"",SUMPRODUCT((((COUNTIF(I13:K13,'2 Courses'!$G$2:$G$200)*('2 Courses'!$G$2:$G$200<>""))+(COUNTIF(I13:K13,'2 Courses'!$H$2:$H$200)*('2 Courses'!$H$2:$H$200<>""))+(COUNTIF(I13:K13,'2 Courses'!$I$2:$I$200)*('2 Courses'!$I$2:$I$200<>"")))>0)*((L13="")+(L13="Diploma or degree")+('2 Courses'!$E$2:$E$200=L13)>0)))
M14: =IF(COUNTA(I14:K14)=0,"",SUMPRODUCT((((COUNTIF(I14:K14,'2 Courses'!$G$2:$G$200)*('2 Courses'!$G$2:$G$200<>""))+(COUNTIF(I14:K14,'2 Courses'!$H$2:$H$200)*('2 Courses'!$H$2:$H$200<>""))+(COUNTIF(I14:K14,'2 Courses'!$I$2:$I$200)*('2 Courses'!$I$2:$I$200<>"")))>0)*((L14="")+(L14="Diploma or degree")+('2 Courses'!$E$2:$E$200=L14)>0)))
... M300: =IF(COUNTA(I300:K300)=0,"",SUMPRODUCT((((COUNTIF(I300:K300,'2 Courses'!$G$2:$G$200)*('2 Courses'!$G$2:$G$200<>""))+(COUNTIF(I300:K300,'2 Courses'!$H$2:$H$200)*('2 Courses'!$H$2:$H$200<>""))+(COUNTIF(I300:K300,'2 Courses'!$I$2:$I$200)*('2 Courses'!$I$2:$I$200<>"")))>0)*((L300="")+(L300="Diploma or degree")+('2 Courses'!$E$2:$E$200=L300)>0)))

Sheet 3 Hazed Questions
A1: Question no. | B1: Question | C1: Answer option | D1: Answer text | E1: Points: med | F1: Points: eng | G1: Points: cs | H1: Points: biz | I1: Points: design | J1: Points: law | K1: Points: edu | L1: Points: sci | M1: Points: hosp | N1: Points: comm | O1: Level it suggests (Q5 only)
A2: Q1 | B2: Which school subjects do you enjoy most? | C2: A | D2: Biology and Chemistry | E2: 2 | L2: 2
A3: Q1 | B3: Which school subjects do you enjoy most? | C3: B | D3: Maths and Physics | F3: 2 | G3: 2
A4: Q1 | B4: Which school subjects do you enjoy most? | C4: C | D4: Accounts and Economics | H4: 3
A5: Q1 | B5: Which school subjects do you enjoy most? | C5: D | D5: Art and Design | I5: 3
A6: Q1 | B6: Which school subjects do you enjoy most? | C6: E | D6: Languages and History | J6: 1 | K6: 1 | N6: 2
A7: Q2 | B7: On a free weekend, what would you rather do? | C7: A | D7: Fix or build something | F7: 3
A8: Q2 | B8: On a free weekend, what would you rather do? | C8: B | D8: Make a video or a poster | I8: 2 | N8: 2
A9: Q2 | B9: On a free weekend, what would you rather do? | C9: C | D9: Help out at a clinic or care home | E9: 3
A10: Q2 | B10: On a free weekend, what would you rather do? | C10: D | D10: Run a small stall or sell something | H10: 2 | M10: 2
A11: Q2 | B11: On a free weekend, what would you rather do? | C11: E | D11: Solve puzzles or write code | G11: 3
A12: Q3 | B12: How do you like to work? | C12: A | D12: With people, face to face | E12: 1 | K12: 2 | M12: 2
A13: Q3 | B13: How do you like to work? | C13: B | D13: With data and numbers | G13: 1 | H13: 2 | L13: 1
A14: Q3 | B14: How do you like to work? | C14: C | D14: With my hands and tools | F14: 2 | I14: 1
A15: Q3 | B15: How do you like to work? | C15: D | D15: With words and arguments | J15: 3 | N15: 1
A16: Q4 | B16: What matters most to you in a future job? | C16: A | D16: A stable income | F16: 2 | H16: 2
A17: Q4 | B17: What matters most to you in a future job? | C17: B | D17: Helping other people | E17: 2 | K17: 2
A18: Q4 | B18: What matters most to you in a future job? | C18: C | D18: Being creative | I18: 2 | N18: 2
A19: Q4 | B19: What matters most to you in a future job? | C19: D | D19: Solving hard problems | G19: 2 | J19: 1 | L19: 2
A20: Q5 | B20: How long are you ready to study before you start working? | C20: A | D20: About 2 years | O20: Diploma
A21: Q5 | B21: How long are you ready to study before you start working? | C21: B | D21: 3 to 4 years | O21: Degree
A22: Q5 | B22: How long are you ready to study before you start working? | C22: C | D22: 5 years or more | O22: Degree (long)
A23: Q5 | B23: How long are you ready to study before you start working? | C23: D | D23: I am not sure yet
A25: How scoring works: each answer adds its points to the fields shown. The two fields with the most points are suggested. Q5 sets the preferred level instead of giving points.

Sheet 3 Hazed Students
A1: Student ID | B1: Date enquired | C1: Full name | D1: Phone / WhatsApp | E1: Email | F1: Latest qualification | G1: School / state | H1: How they found us | I1: Q1 answer | J1: Q2 answer | K1: Q3 answer | L1: Q4 answer | M1: Q5 answer | N1: Score: med | O1: Score: eng | P1: Score: cs | Q1: Score: biz | R1: Score: design | S1: Score: law | T1: Score: edu | U1: Score: sci | V1: Score: hosp | W1: Score: comm | X1: Top field | Y1: Second field | Z1: Preferred level | AA1: Counsellor | AB1: Status | AC1: Next follow-up date | AD1: Consultation date | AE1: Final course | AF1: Final university | AG1: Notes
A2: ST-003 | B2: 46303 | C2: Priya a/p Raman | D2: 013-987 6543 | F2: SPM | G2: SMK Example, Johor | H2: WhatsApp | I2: A | J2: C | K2: A | L2: B | M2: B | N2: =IF(COUNTA(I2:L2)=0,"",SUMIFS('3 Hazed Questions'!$E$2:$E$23,'3 Hazed Questions'!$A$2:$A$23,"Q1",'3 Hazed Questions'!$C$2:$C$23,I2)+SUMIFS('3 Hazed Questions'!$E$2:$E$23,'3 Hazed Questions'!$A$2:$A$23,"Q2",'3 Hazed Questions'!$C$2:$C$23,J2)+SUMIFS('3 Hazed Questions'!$E$2:$E$23,'3 Hazed Questions'!$A$2:$A$23,"Q3",'3 Hazed Questions'!$C$2:$C$23,K2)+SUMIFS('3 Hazed Questions'!$E$2:$E$23,'3 Hazed Questions'!$A$2:$A$23,"Q4",'3 Hazed Questions'!$C$2:$C$23,L2)) -> 8 | O2: =IF(COUNTA(I2:L2)=0,"",SUMIFS('3 Hazed Questions'!$F$2:$F$23,'3 Hazed Questions'!$A$2:$A$23,"Q1",'3 Hazed Questions'!$C$2:$C$23,I2)+SUMIFS('3 Hazed Questions'!$F$2:$F$23,'3 Hazed Questions'!$A$2:$A$23,"Q2",'3 Hazed Questions'!$C$2:$C$23,J2)+SUMIFS('3 Hazed Questions'!$F$2:$F$23,'3 Hazed Questions'!$A$2:$A$23,"Q3",'3 Hazed Questions'!$C$2:$C$23,K2)+SUMIFS('3 Hazed Questions'!$F$2:$F$23,'3 Hazed Questions'!$A$2:$A$23,"Q4",'3 Hazed Questions'!$C$2:$C$23,L2)) -> 0 | P2: =IF(COUNTA(I2:L2)=0,"",SUMIFS('3 Hazed Questions'!$G$2:$G$23,'3 Hazed Questions'!$A$2:$A$23,"Q1",'3 Hazed Questions'!$C$2:$C$23,I2)+SUMIFS('3 Hazed Questions'!$G$2:$G$23,'3 Hazed Questions'!$A$2:$A$23,"Q2",'3 Hazed Questions'!$C$2:$C$23,J2)+SUMIFS('3 Hazed Questions'!$G$2:$G$23,'3 Hazed Questions'!$A$2:$A$23,"Q3",'3 Hazed Questions'!$C$2:$C$23,K2)+SUMIFS('3 Hazed Questions'!$G$2:$G$23,'3 Hazed Questions'!$A$2:$A$23,"Q4",'3 Hazed Questions'!$C$2:$C$23,L2)) -> 0 | Q2: =IF(COUNTA(I2:L2)=0,"",SUMIFS('3 Hazed Questions'!$H$2:$H$23,'3 Hazed Questions'!$A$2:$A$23,"Q1",'3 Hazed Questions'!$C$2:$C$23,I2)+SUMIFS('3 Hazed Questions'!$H$2:$H$23,'3 Hazed Questions'!$A$2:$A$23,"Q2",'3 Hazed Questions'!$C$2:$C$23,J2)+SUMIFS('3 Hazed Questions'!$H$2:$H$23,'3 Hazed Questions'!$A$2:$A$23,"Q3",'3 Hazed Questions'!$C$2:$C$23,K2)+SUMIFS('3 Hazed Questions'!$H$2:$H$23,'3 Hazed Questions'!$A$2:$A$23,"Q4",'3 Hazed Questions'!$C$2:$C$23,L2)) -> 0 | R2: =IF(COUNTA(I2:L2)=0,"",SUMIFS('3 Hazed Questions'!$I$2:$I$23,'3 Hazed Questions'!$A$2:$A$23,"Q1",'3 Hazed Questions'!$C$2:$C$23,I2)+SUMIFS('3 Hazed Questions'!$I$2:$I$23,'3 Hazed Questions'!$A$2:$A$23,"Q2",'3 Hazed Questions'!$C$2:$C$23,J2)+SUMIFS('3 Hazed Questions'!$I$2:$I$23,'3 Hazed Questions'!$A$2:$A$23,"Q3",'3 Hazed Questions'!$C$2:$C$23,K2)+SUMIFS('3 Hazed Questions'!$I$2:$I$23,'3 Hazed Questions'!$A$2:$A$23,"Q4",'3 Hazed Questions'!$C$2:$C$23,L2)) -> 0 | S2: =IF(COUNTA(I2:L2)=0,"",SUMIFS('3 Hazed Questions'!$J$2:$J$23,'3 Hazed Questions'!$A$2:$A$23,"Q1",'3 Hazed Questions'!$C$2:$C$23,I2)+SUMIFS('3 Hazed Questions'!$J$2:$J$23,'3 Hazed Questions'!$A$2:$A$23,"Q2",'3 Hazed Questions'!$C$2:$C$23,J2)+SUMIFS('3 Hazed Questions'!$J$2:$J$23,'3 Hazed Questions'!$A$2:$A$23,"Q3",'3 Hazed Questions'!$C$2:$C$23,K2)+SUMIFS('3 Hazed Questions'!$J$2:$J$23,'3 Hazed Questions'!$A$2:$A$23,"Q4",'3 Hazed Questions'!$C$2:$C$23,L2)) -> 0 | T2: =IF(COUNTA(I2:L2)=0,"",SUMIFS('3 Hazed Questions'!$K$2:$K$23,'3 Hazed Questions'!$A$2:$A$23,"Q1",'3 Hazed Questions'!$C$2:$C$23,I2)+SUMIFS('3 Hazed Questions'!$K$2:$K$23,'3 Hazed Questions'!$A$2:$A$23,"Q2",'3 Hazed Questions'!$C$2:$C$23,J2)+SUMIFS('3 Hazed Questions'!$K$2:$K$23,'3 Hazed Questions'!$A$2:$A$23,"Q3",'3 Hazed Questions'!$C$2:$C$23,K2)+SUMIFS('3 Hazed Questions'!$K$2:$K$23,'3 Hazed Questions'!$A$2:$A$23,"Q4",'3 Hazed Questions'!$C$2:$C$23,L2)) -> 4 | U2: =IF(COUNTA(I2:L2)=0,"",SUMIFS('3 Hazed Questions'!$L$2:$L$23,'3 Hazed Questions'!$A$2:$A$23,"Q1",'3 Hazed Questions'!$C$2:$C$23,I2)+SUMIFS('3 Hazed Questions'!$L$2:$L$23,'3 Hazed Questions'!$A$2:$A$23,"Q2",'3 Hazed Questions'!$C$2:$C$23,J2)+SUMIFS('3 Hazed Questions'!$L$2:$L$23,'3 Hazed Questions'!$A$2:$A$23,"Q3",'3 Hazed Questions'!$C$2:$C$23,K2)+SUMIFS('3 Hazed Questions'!$L$2:$L$23,'3 Hazed Questions'!$A$2:$A$23,"Q4",'3 Hazed Questions'!$C$2:$C$23,L2)) -> 2 | V2: =IF(COUNTA(I2:L2)=0,"",SUMIFS('3 Hazed Questions'!$M$2:$M$23,'3 Hazed Questions'!$A$2:$A$23,"Q1",'3 Hazed Questions'!$C$2:$C$23,I2)+SUMIFS('3 Hazed Questions'!$M$2:$M$23,'3 Hazed Questions'!$A$2:$A$23,"Q2",'3 Hazed Questions'!$C$2:$C$23,J2)+SUMIFS('3 Hazed Questions'!$M$2:$M$23,'3 Hazed Questions'!$A$2:$A$23,"Q3",'3 Hazed Questions'!$C$2:$C$23,K2)+SUMIFS('3 Hazed Questions'!$M$2:$M$23,'3 Hazed Questions'!$A$2:$A$23,"Q4",'3 Hazed Questions'!$C$2:$C$23,L2)) -> 2 | W2: =IF(COUNTA(I2:L2)=0,"",SUMIFS('3 Hazed Questions'!$N$2:$N$23,'3 Hazed Questions'!$A$2:$A$23,"Q1",'3 Hazed Questions'!$C$2:$C$23,I2)+SUMIFS('3 Hazed Questions'!$N$2:$N$23,'3 Hazed Questions'!$A$2:$A$23,"Q2",'3 Hazed Questions'!$C$2:$C$23,J2)+SUMIFS('3 Hazed Questions'!$N$2:$N$23,'3 Hazed Questions'!$A$2:$A$23,"Q3",'3 Hazed Questions'!$C$2:$C$23,K2)+SUMIFS('3 Hazed Questions'!$N$2:$N$23,'3 Hazed Questions'!$A$2:$A$23,"Q4",'3 Hazed Questions'!$C$2:$C$23,L2)) -> 0 | X2: =IF(COUNTA(I2:L2)=0,"",INDEX(Fields!$B$2:$B$50,MATCH(SUBSTITUTE(INDEX($N$1:$W$1,MATCH(MAX($N2:$W2),$N2:$W2,0)),"Score: ",""),Fields!$A$2:$A$50,0))) -> Medicine & Health | Y2: =IF(COUNTA(I2:L2)=0,"",IF(LARGE($N2:$W2,2)=0,"-",INDEX(Fields!$B$2:$B$50,MATCH(SUBSTITUTE(INDEX($N$1:$W$1,IF(LARGE($N2:$W2,2)=MAX($N2:$W2),MATCH(MAX($N2:$W2),OFFSET($N2:$W2,0,MATCH(MAX($N2:$W2),$N2:$W2,0),1,10-MATCH(MAX($N2:$W2),$N2:$W2,0)),0)+MATCH(MAX($N2:$W2),$N2:$W2,0),MATCH(LARGE($N2:$W2,2),$N2:$W2,0))),"Score: ",""),Fields!$A$2:$A$50,0)))) -> Education | Z2: =IF(M2="","",IFERROR(INDEX('3 Hazed Questions'!$O$2:$O$23,MATCH(1,INDEX(('3 Hazed Questions'!$A$2:$A$23="Q5")*('3 Hazed Questions'!$C$2:$C$23=M2),0),0))&"","")) -> Degree | AA2: Ahmad | AB2: New | AC2: 46305
N3: =IF(COUNTA(I3:L3)=0,"",SUMIFS('3 Hazed Questions'!$E$2:$E$23,'3 Hazed Questions'!$A$2:$A$23,"Q1",'3 Hazed Questions'!$C$2:$C$23,I3)+SUMIFS('3 Hazed Questions'!$E$2:$E$23,'3 Hazed Questions'!$A$2:$A$23,"Q2",'3 Hazed Questions'!$C$2:$C$23,J3)+SUMIFS('3 Hazed Questions'!$E$2:$E$23,'3 Hazed Questions'!$A$2:$A$23,"Q3",'3 Hazed Questions'!$C$2:$C$23,K3)+SUMIFS('3 Hazed Questions'!$E$2:$E$23,'3 Hazed Questions'!$A$2:$A$23,"Q4",'3 Hazed Questions'!$C$2:$C$23,L3)) | O3: =IF(COUNTA(I3:L3)=0,"",SUMIFS('3 Hazed Questions'!$F$2:$F$23,'3 Hazed Questions'!$A$2:$A$23,"Q1",'3 Hazed Questions'!$C$2:$C$23,I3)+SUMIFS('3 Hazed Questions'!$F$2:$F$23,'3 Hazed Questions'!$A$2:$A$23,"Q2",'3 Hazed Questions'!$C$2:$C$23,J3)+SUMIFS('3 Hazed Questions'!$F$2:$F$23,'3 Hazed Questions'!$A$2:$A$23,"Q3",'3 Hazed Questions'!$C$2:$C$23,K3)+SUMIFS('3 Hazed Questions'!$F$2:$F$23,'3 Hazed Questions'!$A$2:$A$23,"Q4",'3 Hazed Questions'!$C$2:$C$23,L3)) | P3: =IF(COUNTA(I3:L3)=0,"",SUMIFS('3 Hazed Questions'!$G$2:$G$23,'3 Hazed Questions'!$A$2:$A$23,"Q1",'3 Hazed Questions'!$C$2:$C$23,I3)+SUMIFS('3 Hazed Questions'!$G$2:$G$23,'3 Hazed Questions'!$A$2:$A$23,"Q2",'3 Hazed Questions'!$C$2:$C$23,J3)+SUMIFS('3 Hazed Questions'!$G$2:$G$23,'3 Hazed Questions'!$A$2:$A$23,"Q3",'3 Hazed Questions'!$C$2:$C$23,K3)+SUMIFS('3 Hazed Questions'!$G$2:$G$23,'3 Hazed Questions'!$A$2:$A$23,"Q4",'3 Hazed Questions'!$C$2:$C$23,L3)) | Q3: =IF(COUNTA(I3:L3)=0,"",SUMIFS('3 Hazed Questions'!$H$2:$H$23,'3 Hazed Questions'!$A$2:$A$23,"Q1",'3 Hazed Questions'!$C$2:$C$23,I3)+SUMIFS('3 Hazed Questions'!$H$2:$H$23,'3 Hazed Questions'!$A$2:$A$23,"Q2",'3 Hazed Questions'!$C$2:$C$23,J3)+SUMIFS('3 Hazed Questions'!$H$2:$H$23,'3 Hazed Questions'!$A$2:$A$23,"Q3",'3 Hazed Questions'!$C$2:$C$23,K3)+SUMIFS('3 Hazed Questions'!$H$2:$H$23,'3 Hazed Questions'!$A$2:$A$23,"Q4",'3 Hazed Questions'!$C$2:$C$23,L3)) | R3: =IF(COUNTA(I3:L3)=0,"",SUMIFS('3 Hazed Questions'!$I$2:$I$23,'3 Hazed Questions'!$A$2:$A$23,"Q1",'3 Hazed Questions'!$C$2:$C$23,I3)+SUMIFS('3 Hazed Questions'!$I$2:$I$23,'3 Hazed Questions'!$A$2:$A$23,"Q2",'3 Hazed Questions'!$C$2:$C$23,J3)+SUMIFS('3 Hazed Questions'!$I$2:$I$23,'3 Hazed Questions'!$A$2:$A$23,"Q3",'3 Hazed Questions'!$C$2:$C$23,K3)+SUMIFS('3 Hazed Questions'!$I$2:$I$23,'3 Hazed Questions'!$A$2:$A$23,"Q4",'3 Hazed Questions'!$C$2:$C$23,L3)) | S3: =IF(COUNTA(I3:L3)=0,"",SUMIFS('3 Hazed Questions'!$J$2:$J$23,'3 Hazed Questions'!$A$2:$A$23,"Q1",'3 Hazed Questions'!$C$2:$C$23,I3)+SUMIFS('3 Hazed Questions'!$J$2:$J$23,'3 Hazed Questions'!$A$2:$A$23,"Q2",'3 Hazed Questions'!$C$2:$C$23,J3)+SUMIFS('3 Hazed Questions'!$J$2:$J$23,'3 Hazed Questions'!$A$2:$A$23,"Q3",'3 Hazed Questions'!$C$2:$C$23,K3)+SUMIFS('3 Hazed Questions'!$J$2:$J$23,'3 Hazed Questions'!$A$2:$A$23,"Q4",'3 Hazed Questions'!$C$2:$C$23,L3)) | T3: =IF(COUNTA(I3:L3)=0,"",SUMIFS('3 Hazed Questions'!$K$2:$K$23,'3 Hazed Questions'!$A$2:$A$23,"Q1",'3 Hazed Questions'!$C$2:$C$23,I3)+SUMIFS('3 Hazed Questions'!$K$2:$K$23,'3 Hazed Questions'!$A$2:$A$23,"Q2",'3 Hazed Questions'!$C$2:$C$23,J3)+SUMIFS('3 Hazed Questions'!$K$2:$K$23,'3 Hazed Questions'!$A$2:$A$23,"Q3",'3 Hazed Questions'!$C$2:$C$23,K3)+SUMIFS('3 Hazed Questions'!$K$2:$K$23,'3 Hazed Questions'!$A$2:$A$23,"Q4",'3 Hazed Questions'!$C$2:$C$23,L3)) | U3: =IF(COUNTA(I3:L3)=0,"",SUMIFS('3 Hazed Questions'!$L$2:$L$23,'3 Hazed Questions'!$A$2:$A$23,"Q1",'3 Hazed Questions'!$C$2:$C$23,I3)+SUMIFS('3 Hazed Questions'!$L$2:$L$23,'3 Hazed Questions'!$A$2:$A$23,"Q2",'3 Hazed Questions'!$C$2:$C$23,J3)+SUMIFS('3 Hazed Questions'!$L$2:$L$23,'3 Hazed Questions'!$A$2:$A$23,"Q3",'3 Hazed Questions'!$C$2:$C$23,K3)+SUMIFS('3 Hazed Questions'!$L$2:$L$23,'3 Hazed Questions'!$A$2:$A$23,"Q4",'3 Hazed Questions'!$C$2:$C$23,L3)) | V3: =IF(COUNTA(I3:L3)=0,"",SUMIFS('3 Hazed Questions'!$M$2:$M$23,'3 Hazed Questions'!$A$2:$A$23,"Q1",'3 Hazed Questions'!$C$2:$C$23,I3)+SUMIFS('3 Hazed Questions'!$M$2:$M$23,'3 Hazed Questions'!$A$2:$A$23,"Q2",'3 Hazed Questions'!$C$2:$C$23,J3)+SUMIFS('3 Hazed Questions'!$M$2:$M$23,'3 Hazed Questions'!$A$2:$A$23,"Q3",'3 Hazed Questions'!$C$2:$C$23,K3)+SUMIFS('3 Hazed Questions'!$M$2:$M$23,'3 Hazed Questions'!$A$2:$A$23,"Q4",'3 Hazed Questions'!$C$2:$C$23,L3)) | W3: =IF(COUNTA(I3:L3)=0,"",SUMIFS('3 Hazed Questions'!$N$2:$N$23,'3 Hazed Questions'!$A$2:$A$23,"Q1",'3 Hazed Questions'!$C$2:$C$23,I3)+SUMIFS('3 Hazed Questions'!$N$2:$N$23,'3 Hazed Questions'!$A$2:$A$23,"Q2",'3 Hazed Questions'!$C$2:$C$23,J3)+SUMIFS('3 Hazed Questions'!$N$2:$N$23,'3 Hazed Questions'!$A$2:$A$23,"Q3",'3 Hazed Questions'!$C$2:$C$23,K3)+SUMIFS('3 Hazed Questions'!$N$2:$N$23,'3 Hazed Questions'!$A$2:$A$23,"Q4",'3 Hazed Questions'!$C$2:$C$23,L3)) | X3: =IF(COUNTA(I3:L3)=0,"",INDEX(Fields!$B$2:$B$50,MATCH(SUBSTITUTE(INDEX($N$1:$W$1,MATCH(MAX($N3:$W3),$N3:$W3,0)),"Score: ",""),Fields!$A$2:$A$50,0))) | Y3: =IF(COUNTA(I3:L3)=0,"",IF(LARGE($N3:$W3,2)=0,"-",INDEX(Fields!$B$2:$B$50,MATCH(SUBSTITUTE(INDEX($N$1:$W$1,IF(LARGE($N3:$W3,2)=MAX($N3:$W3),MATCH(MAX($N3:$W3),OFFSET($N3:$W3,0,MATCH(MAX($N3:$W3),$N3:$W3,0),1,10-MATCH(MAX($N3:$W3),$N3:$W3,0)),0)+MATCH(MAX($N3:$W3),$N3:$W3,0),MATCH(LARGE($N3:$W3,2),$N3:$W3,0))),"Score: ",""),Fields!$A$2:$A$50,0)))) | Z3: =IF(M3="","",IFERROR(INDEX('3 Hazed Questions'!$O$2:$O$23,MATCH(1,INDEX(('3 Hazed Questions'!$A$2:$A$23="Q5")*('3 Hazed Questions'!$C$2:$C$23=M3),0),0))&"",""))
N4: =IF(COUNTA(I4:L4)=0,"",SUMIFS('3 Hazed Questions'!$E$2:$E$23,'3 Hazed Questions'!$A$2:$A$23,"Q1",'3 Hazed Questions'!$C$2:$C$23,I4)+SUMIFS('3 Hazed Questions'!$E$2:$E$23,'3 Hazed Questions'!$A$2:$A$23,"Q2",'3 Hazed Questions'!$C$2:$C$23,J4)+SUMIFS('3 Hazed Questions'!$E$2:$E$23,'3 Hazed Questions'!$A$2:$A$23,"Q3",'3 Hazed Questions'!$C$2:$C$23,K4)+SUMIFS('3 Hazed Questions'!$E$2:$E$23,'3 Hazed Questions'!$A$2:$A$23,"Q4",'3 Hazed Questions'!$C$2:$C$23,L4)) | O4: =IF(COUNTA(I4:L4)=0,"",SUMIFS('3 Hazed Questions'!$F$2:$F$23,'3 Hazed Questions'!$A$2:$A$23,"Q1",'3 Hazed Questions'!$C$2:$C$23,I4)+SUMIFS('3 Hazed Questions'!$F$2:$F$23,'3 Hazed Questions'!$A$2:$A$23,"Q2",'3 Hazed Questions'!$C$2:$C$23,J4)+SUMIFS('3 Hazed Questions'!$F$2:$F$23,'3 Hazed Questions'!$A$2:$A$23,"Q3",'3 Hazed Questions'!$C$2:$C$23,K4)+SUMIFS('3 Hazed Questions'!$F$2:$F$23,'3 Hazed Questions'!$A$2:$A$23,"Q4",'3 Hazed Questions'!$C$2:$C$23,L4)) | P4: =IF(COUNTA(I4:L4)=0,"",SUMIFS('3 Hazed Questions'!$G$2:$G$23,'3 Hazed Questions'!$A$2:$A$23,"Q1",'3 Hazed Questions'!$C$2:$C$23,I4)+SUMIFS('3 Hazed Questions'!$G$2:$G$23,'3 Hazed Questions'!$A$2:$A$23,"Q2",'3 Hazed Questions'!$C$2:$C$23,J4)+SUMIFS('3 Hazed Questions'!$G$2:$G$23,'3 Hazed Questions'!$A$2:$A$23,"Q3",'3 Hazed Questions'!$C$2:$C$23,K4)+SUMIFS('3 Hazed Questions'!$G$2:$G$23,'3 Hazed Questions'!$A$2:$A$23,"Q4",'3 Hazed Questions'!$C$2:$C$23,L4)) | Q4: =IF(COUNTA(I4:L4)=0,"",SUMIFS('3 Hazed Questions'!$H$2:$H$23,'3 Hazed Questions'!$A$2:$A$23,"Q1",'3 Hazed Questions'!$C$2:$C$23,I4)+SUMIFS('3 Hazed Questions'!$H$2:$H$23,'3 Hazed Questions'!$A$2:$A$23,"Q2",'3 Hazed Questions'!$C$2:$C$23,J4)+SUMIFS('3 Hazed Questions'!$H$2:$H$23,'3 Hazed Questions'!$A$2:$A$23,"Q3",'3 Hazed Questions'!$C$2:$C$23,K4)+SUMIFS('3 Hazed Questions'!$H$2:$H$23,'3 Hazed Questions'!$A$2:$A$23,"Q4",'3 Hazed Questions'!$C$2:$C$23,L4)) | R4: =IF(COUNTA(I4:L4)=0,"",SUMIFS('3 Hazed Questions'!$I$2:$I$23,'3 Hazed Questions'!$A$2:$A$23,"Q1",'3 Hazed Questions'!$C$2:$C$23,I4)+SUMIFS('3 Hazed Questions'!$I$2:$I$23,'3 Hazed Questions'!$A$2:$A$23,"Q2",'3 Hazed Questions'!$C$2:$C$23,J4)+SUMIFS('3 Hazed Questions'!$I$2:$I$23,'3 Hazed Questions'!$A$2:$A$23,"Q3",'3 Hazed Questions'!$C$2:$C$23,K4)+SUMIFS('3 Hazed Questions'!$I$2:$I$23,'3 Hazed Questions'!$A$2:$A$23,"Q4",'3 Hazed Questions'!$C$2:$C$23,L4)) | S4: =IF(COUNTA(I4:L4)=0,"",SUMIFS('3 Hazed Questions'!$J$2:$J$23,'3 Hazed Questions'!$A$2:$A$23,"Q1",'3 Hazed Questions'!$C$2:$C$23,I4)+SUMIFS('3 Hazed Questions'!$J$2:$J$23,'3 Hazed Questions'!$A$2:$A$23,"Q2",'3 Hazed Questions'!$C$2:$C$23,J4)+SUMIFS('3 Hazed Questions'!$J$2:$J$23,'3 Hazed Questions'!$A$2:$A$23,"Q3",'3 Hazed Questions'!$C$2:$C$23,K4)+SUMIFS('3 Hazed Questions'!$J$2:$J$23,'3 Hazed Questions'!$A$2:$A$23,"Q4",'3 Hazed Questions'!$C$2:$C$23,L4)) | T4: =IF(COUNTA(I4:L4)=0,"",SUMIFS('3 Hazed Questions'!$K$2:$K$23,'3 Hazed Questions'!$A$2:$A$23,"Q1",'3 Hazed Questions'!$C$2:$C$23,I4)+SUMIFS('3 Hazed Questions'!$K$2:$K$23,'3 Hazed Questions'!$A$2:$A$23,"Q2",'3 Hazed Questions'!$C$2:$C$23,J4)+SUMIFS('3 Hazed Questions'!$K$2:$K$23,'3 Hazed Questions'!$A$2:$A$23,"Q3",'3 Hazed Questions'!$C$2:$C$23,K4)+SUMIFS('3 Hazed Questions'!$K$2:$K$23,'3 Hazed Questions'!$A$2:$A$23,"Q4",'3 Hazed Questions'!$C$2:$C$23,L4)) | U4: =IF(COUNTA(I4:L4)=0,"",SUMIFS('3 Hazed Questions'!$L$2:$L$23,'3 Hazed Questions'!$A$2:$A$23,"Q1",'3 Hazed Questions'!$C$2:$C$23,I4)+SUMIFS('3 Hazed Questions'!$L$2:$L$23,'3 Hazed Questions'!$A$2:$A$23,"Q2",'3 Hazed Questions'!$C$2:$C$23,J4)+SUMIFS('3 Hazed Questions'!$L$2:$L$23,'3 Hazed Questions'!$A$2:$A$23,"Q3",'3 Hazed Questions'!$C$2:$C$23,K4)+SUMIFS('3 Hazed Questions'!$L$2:$L$23,'3 Hazed Questions'!$A$2:$A$23,"Q4",'3 Hazed Questions'!$C$2:$C$23,L4)) | V4: =IF(COUNTA(I4:L4)=0,"",SUMIFS('3 Hazed Questions'!$M$2:$M$23,'3 Hazed Questions'!$A$2:$A$23,"Q1",'3 Hazed Questions'!$C$2:$C$23,I4)+SUMIFS('3 Hazed Questions'!$M$2:$M$23,'3 Hazed Questions'!$A$2:$A$23,"Q2",'3 Hazed Questions'!$C$2:$C$23,J4)+SUMIFS('3 Hazed Questions'!$M$2:$M$23,'3 Hazed Questions'!$A$2:$A$23,"Q3",'3 Hazed Questions'!$C$2:$C$23,K4)+SUMIFS('3 Hazed Questions'!$M$2:$M$23,'3 Hazed Questions'!$A$2:$A$23,"Q4",'3 Hazed Questions'!$C$2:$C$23,L4)) | W4: =IF(COUNTA(I4:L4)=0,"",SUMIFS('3 Hazed Questions'!$N$2:$N$23,'3 Hazed Questions'!$A$2:$A$23,"Q1",'3 Hazed Questions'!$C$2:$C$23,I4)+SUMIFS('3 Hazed Questions'!$N$2:$N$23,'3 Hazed Questions'!$A$2:$A$23,"Q2",'3 Hazed Questions'!$C$2:$C$23,J4)+SUMIFS('3 Hazed Questions'!$N$2:$N$23,'3 Hazed Questions'!$A$2:$A$23,"Q3",'3 Hazed Questions'!$C$2:$C$23,K4)+SUMIFS('3 Hazed Questions'!$N$2:$N$23,'3 Hazed Questions'!$A$2:$A$23,"Q4",'3 Hazed Questions'!$C$2:$C$23,L4)) | X4: =IF(COUNTA(I4:L4)=0,"",INDEX(Fields!$B$2:$B$50,MATCH(SUBSTITUTE(INDEX($N$1:$W$1,MATCH(MAX($N4:$W4),$N4:$W4,0)),"Score: ",""),Fields!$A$2:$A$50,0))) | Y4: =IF(COUNTA(I4:L4)=0,"",IF(LARGE($N4:$W4,2)=0,"-",INDEX(Fields!$B$2:$B$50,MATCH(SUBSTITUTE(INDEX($N$1:$W$1,IF(LARGE($N4:$W4,2)=MAX($N4:$W4),MATCH(MAX($N4:$W4),OFFSET($N4:$W4,0,MATCH(MAX($N4:$W4),$N4:$W4,0),1,10-MATCH(MAX($N4:$W4),$N4:$W4,0)),0)+MATCH(MAX($N4:$W4),$N4:$W4,0),MATCH(LARGE($N4:$W4,2),$N4:$W4,0))),"Score: ",""),Fields!$A$2:$A$50,0)))) | Z4: =IF(M4="","",IFERROR(INDEX('3 Hazed Questions'!$O$2:$O$23,MATCH(1,INDEX(('3 Hazed Questions'!$A$2:$A$23="Q5")*('3 Hazed Questions'!$C$2:$C$23=M4),0),0))&"",""))
N5: =IF(COUNTA(I5:L5)=0,"",SUMIFS('3 Hazed Questions'!$E$2:$E$23,'3 Hazed Questions'!$A$2:$A$23,"Q1",'3 Hazed Questions'!$C$2:$C$23,I5)+SUMIFS('3 Hazed Questions'!$E$2:$E$23,'3 Hazed Questions'!$A$2:$A$23,"Q2",'3 Hazed Questions'!$C$2:$C$23,J5)+SUMIFS('3 Hazed Questions'!$E$2:$E$23,'3 Hazed Questions'!$A$2:$A$23,"Q3",'3 Hazed Questions'!$C$2:$C$23,K5)+SUMIFS('3 Hazed Questions'!$E$2:$E$23,'3 Hazed Questions'!$A$2:$A$23,"Q4",'3 Hazed Questions'!$C$2:$C$23,L5)) | O5: =IF(COUNTA(I5:L5)=0,"",SUMIFS('3 Hazed Questions'!$F$2:$F$23,'3 Hazed Questions'!$A$2:$A$23,"Q1",'3 Hazed Questions'!$C$2:$C$23,I5)+SUMIFS('3 Hazed Questions'!$F$2:$F$23,'3 Hazed Questions'!$A$2:$A$23,"Q2",'3 Hazed Questions'!$C$2:$C$23,J5)+SUMIFS('3 Hazed Questions'!$F$2:$F$23,'3 Hazed Questions'!$A$2:$A$23,"Q3",'3 Hazed Questions'!$C$2:$C$23,K5)+SUMIFS('3 Hazed Questions'!$F$2:$F$23,'3 Hazed Questions'!$A$2:$A$23,"Q4",'3 Hazed Questions'!$C$2:$C$23,L5)) | P5: =IF(COUNTA(I5:L5)=0,"",SUMIFS('3 Hazed Questions'!$G$2:$G$23,'3 Hazed Questions'!$A$2:$A$23,"Q1",'3 Hazed Questions'!$C$2:$C$23,I5)+SUMIFS('3 Hazed Questions'!$G$2:$G$23,'3 Hazed Questions'!$A$2:$A$23,"Q2",'3 Hazed Questions'!$C$2:$C$23,J5)+SUMIFS('3 Hazed Questions'!$G$2:$G$23,'3 Hazed Questions'!$A$2:$A$23,"Q3",'3 Hazed Questions'!$C$2:$C$23,K5)+SUMIFS('3 Hazed Questions'!$G$2:$G$23,'3 Hazed Questions'!$A$2:$A$23,"Q4",'3 Hazed Questions'!$C$2:$C$23,L5)) | Q5: =IF(COUNTA(I5:L5)=0,"",SUMIFS('3 Hazed Questions'!$H$2:$H$23,'3 Hazed Questions'!$A$2:$A$23,"Q1",'3 Hazed Questions'!$C$2:$C$23,I5)+SUMIFS('3 Hazed Questions'!$H$2:$H$23,'3 Hazed Questions'!$A$2:$A$23,"Q2",'3 Hazed Questions'!$C$2:$C$23,J5)+SUMIFS('3 Hazed Questions'!$H$2:$H$23,'3 Hazed Questions'!$A$2:$A$23,"Q3",'3 Hazed Questions'!$C$2:$C$23,K5)+SUMIFS('3 Hazed Questions'!$H$2:$H$23,'3 Hazed Questions'!$A$2:$A$23,"Q4",'3 Hazed Questions'!$C$2:$C$23,L5)) | R5: =IF(COUNTA(I5:L5)=0,"",SUMIFS('3 Hazed Questions'!$I$2:$I$23,'3 Hazed Questions'!$A$2:$A$23,"Q1",'3 Hazed Questions'!$C$2:$C$23,I5)+SUMIFS('3 Hazed Questions'!$I$2:$I$23,'3 Hazed Questions'!$A$2:$A$23,"Q2",'3 Hazed Questions'!$C$2:$C$23,J5)+SUMIFS('3 Hazed Questions'!$I$2:$I$23,'3 Hazed Questions'!$A$2:$A$23,"Q3",'3 Hazed Questions'!$C$2:$C$23,K5)+SUMIFS('3 Hazed Questions'!$I$2:$I$23,'3 Hazed Questions'!$A$2:$A$23,"Q4",'3 Hazed Questions'!$C$2:$C$23,L5)) | S5: =IF(COUNTA(I5:L5)=0,"",SUMIFS('3 Hazed Questions'!$J$2:$J$23,'3 Hazed Questions'!$A$2:$A$23,"Q1",'3 Hazed Questions'!$C$2:$C$23,I5)+SUMIFS('3 Hazed Questions'!$J$2:$J$23,'3 Hazed Questions'!$A$2:$A$23,"Q2",'3 Hazed Questions'!$C$2:$C$23,J5)+SUMIFS('3 Hazed Questions'!$J$2:$J$23,'3 Hazed Questions'!$A$2:$A$23,"Q3",'3 Hazed Questions'!$C$2:$C$23,K5)+SUMIFS('3 Hazed Questions'!$J$2:$J$23,'3 Hazed Questions'!$A$2:$A$23,"Q4",'3 Hazed Questions'!$C$2:$C$23,L5)) | T5: =IF(COUNTA(I5:L5)=0,"",SUMIFS('3 Hazed Questions'!$K$2:$K$23,'3 Hazed Questions'!$A$2:$A$23,"Q1",'3 Hazed Questions'!$C$2:$C$23,I5)+SUMIFS('3 Hazed Questions'!$K$2:$K$23,'3 Hazed Questions'!$A$2:$A$23,"Q2",'3 Hazed Questions'!$C$2:$C$23,J5)+SUMIFS('3 Hazed Questions'!$K$2:$K$23,'3 Hazed Questions'!$A$2:$A$23,"Q3",'3 Hazed Questions'!$C$2:$C$23,K5)+SUMIFS('3 Hazed Questions'!$K$2:$K$23,'3 Hazed Questions'!$A$2:$A$23,"Q4",'3 Hazed Questions'!$C$2:$C$23,L5)) | U5: =IF(COUNTA(I5:L5)=0,"",SUMIFS('3 Hazed Questions'!$L$2:$L$23,'3 Hazed Questions'!$A$2:$A$23,"Q1",'3 Hazed Questions'!$C$2:$C$23,I5)+SUMIFS('3 Hazed Questions'!$L$2:$L$23,'3 Hazed Questions'!$A$2:$A$23,"Q2",'3 Hazed Questions'!$C$2:$C$23,J5)+SUMIFS('3 Hazed Questions'!$L$2:$L$23,'3 Hazed Questions'!$A$2:$A$23,"Q3",'3 Hazed Questions'!$C$2:$C$23,K5)+SUMIFS('3 Hazed Questions'!$L$2:$L$23,'3 Hazed Questions'!$A$2:$A$23,"Q4",'3 Hazed Questions'!$C$2:$C$23,L5)) | V5: =IF(COUNTA(I5:L5)=0,"",SUMIFS('3 Hazed Questions'!$M$2:$M$23,'3 Hazed Questions'!$A$2:$A$23,"Q1",'3 Hazed Questions'!$C$2:$C$23,I5)+SUMIFS('3 Hazed Questions'!$M$2:$M$23,'3 Hazed Questions'!$A$2:$A$23,"Q2",'3 Hazed Questions'!$C$2:$C$23,J5)+SUMIFS('3 Hazed Questions'!$M$2:$M$23,'3 Hazed Questions'!$A$2:$A$23,"Q3",'3 Hazed Questions'!$C$2:$C$23,K5)+SUMIFS('3 Hazed Questions'!$M$2:$M$23,'3 Hazed Questions'!$A$2:$A$23,"Q4",'3 Hazed Questions'!$C$2:$C$23,L5)) | W5: =IF(COUNTA(I5:L5)=0,"",SUMIFS('3 Hazed Questions'!$N$2:$N$23,'3 Hazed Questions'!$A$2:$A$23,"Q1",'3 Hazed Questions'!$C$2:$C$23,I5)+SUMIFS('3 Hazed Questions'!$N$2:$N$23,'3 Hazed Questions'!$A$2:$A$23,"Q2",'3 Hazed Questions'!$C$2:$C$23,J5)+SUMIFS('3 Hazed Questions'!$N$2:$N$23,'3 Hazed Questions'!$A$2:$A$23,"Q3",'3 Hazed Questions'!$C$2:$C$23,K5)+SUMIFS('3 Hazed Questions'!$N$2:$N$23,'3 Hazed Questions'!$A$2:$A$23,"Q4",'3 Hazed Questions'!$C$2:$C$23,L5)) | X5: =IF(COUNTA(I5:L5)=0,"",INDEX(Fields!$B$2:$B$50,MATCH(SUBSTITUTE(INDEX($N$1:$W$1,MATCH(MAX($N5:$W5),$N5:$W5,0)),"Score: ",""),Fields!$A$2:$A$50,0))) | Y5: =IF(COUNTA(I5:L5)=0,"",IF(LARGE($N5:$W5,2)=0,"-",INDEX(Fields!$B$2:$B$50,MATCH(SUBSTITUTE(INDEX($N$1:$W$1,IF(LARGE($N5:$W5,2)=MAX($N5:$W5),MATCH(MAX($N5:$W5),OFFSET($N5:$W5,0,MATCH(MAX($N5:$W5),$N5:$W5,0),1,10-MATCH(MAX($N5:$W5),$N5:$W5,0)),0)+MATCH(MAX($N5:$W5),$N5:$W5,0),MATCH(LARGE($N5:$W5,2),$N5:$W5,0))),"Score: ",""),Fields!$A$2:$A$50,0)))) | Z5: =IF(M5="","",IFERROR(INDEX('3 Hazed Questions'!$O$2:$O$23,MATCH(1,INDEX(('3 Hazed Questions'!$A$2:$A$23="Q5")*('3 Hazed Questions'!$C$2:$C$23=M5),0),0))&"",""))
